[*] Traceback (most recent call last):
  File "artifect_find.py", line 225, in main
    parseDEX()
  File "artifect_find.py", line 124, in parseDEX
    findSuspicious(string)
  File "artifect_find.py", line 100, in findSuspicious
    ip 		= re.findall(r'^\d{1,3}\.\d{1,3}\.\d{1,3}\.\d{1,3}$', stringlist[i])
  File "/usr/lib/python3.4/re.py", line 210, in findall
    return _compile(pattern, flags).findall(string)
TypeError: can't use a string pattern on a bytes-like object

[*] Traceback (most recent call last):
  File "artifect_find.py", line 225, in main
    parseDEX()
  File "artifect_find.py", line 124, in parseDEX
    findSuspicious(string)
  File "artifect_find.py", line 100, in findSuspicious
    ip 	= re.findall(b'^\d{1,3}\.\d{1,3}\.\d{1,3}\.\d{1,3}$', stringlist[i]).decode('utf-8')
AttributeError: 'list' object has no attribute 'decode'

[*] Traceback (most recent call last):
  File "artifect_find.py", line 230, in main
    parse_icon(apkfile)
  File "artifect_find.py", line 191, in parse_icon
    if (filename.find >= 0):
TypeError: unorderable types: builtin_function_or_method() >= int()

[*] Traceback (most recent call last):
  File "artifect_find.py", line 232, in main
    getManifest(apkfile)
  File "artifect_find.py", line 91, in getManifest
    subprocess.call(infocmd > result.txt,shell=True)
NameError: name 'result' is not defined

[*] Traceback (most recent call last):
  File "artifect_find.py", line 234, in main
    getManifest(apkfile)
  File "artifect_find.py", line 92, in getManifest
    data = result.read().strip()
AttributeError: 'int' object has no attribute 'read'

[*] Traceback (most recent call last):
  File "artifect_find.py", line 235, in main
    getManifest(apkfile)
  File "artifect_find.py", line 91, in getManifest
    result = subprocess.Popen(infocmd,stdout=subprocess.PIPE).stdout
  File "/usr/lib/python3.4/subprocess.py", line 859, in __init__
    restore_signals, start_new_session)
  File "/usr/lib/python3.4/subprocess.py", line 1457, in _execute_child
    raise child_exception_type(errno_num, err_msg)
FileNotFoundError: [Errno 2] No such file or directory: 'aapt dump badging AsaraTTA.apk | grep uses-permission'

[*] Traceback (most recent call last):
  File "artifect_find.py", line 235, in main
    getManifest(apkfile)
  File "artifect_find.py", line 93, in getManifest
    for i in range(len(f)):
TypeError: object of type '_io.TextIOWrapper' has no len()

[*] Traceback (most recent call last):
  File "artifect_find.py", line 243, in main
    getManifest(apkfile)
TypeError: getManifest() missing 1 required positional argument: 'apkfile'

[*] Traceback (most recent call last):
  File "artifect_find.py", line 243, in main
    getManifest(cur,apkfile)
NameError: name 'cur' is not defined

[*] Traceback (most recent call last):
  File "artifect_find.py", line 243, in main
    getManifest(apkfile)
  File "artifect_find.py", line 100, in getManifest
    mysql_list.append(line)
AttributeError: 'str' object has no attribute 'append'

[*] Traceback (most recent call last):
  File "artifect_find.py", line 243, in main
    getManifest(apkfile)
  File "artifect_find.py", line 100, in getManifest
    mysql_list.append(str(line))
AttributeError: 'str' object has no attribute 'append'

[*] Traceback (most recent call last):
  File "artifect_find.py", line 244, in main
    getManifest(apkfile)
  File "artifect_find.py", line 100, in getManifest
    mysql_list.join('.',line)
TypeError: join() takes exactly one argument (2 given)

[*] Traceback (most recent call last):
  File "artifect_find.py", line 251, in main
    parseDEX()
  File "artifect_find.py", line 142, in parseDEX
    findSuspicious(string)
  File "artifect_find.py", line 122, in findSuspicious
    urllist += (str(url[0])).translate(None,"\'")
TypeError: translate() takes exactly one argument (2 given)

[*] Traceback (most recent call last):
  File "artifect_find.py", line 251, in main
    parseDEX()
  File "artifect_find.py", line 142, in parseDEX
    findSuspicious(string)
  File "artifect_find.py", line 122, in findSuspicious
    urllist += (str(url[0])).translate(None,"'")
TypeError: translate() takes exactly one argument (2 given)

[*] Traceback (most recent call last):
  File "artifect_find.py", line 267, in main
    parseDEX()
  File "artifect_find.py", line 156, in parseDEX
    findSuspicious(string)
  File "artifect_find.py", line 123, in findSuspicious
    if url.find("schemas.android.com") >= 0:
AttributeError: 'list' object has no attribute 'find'

[*] Traceback (most recent call last):
  File "artifect_find.py", line 267, in main
    parseDEX()
  File "artifect_find.py", line 156, in parseDEX
    findSuspicious(string)
  File "artifect_find.py", line 123, in findSuspicious
    if url[0].find("schemas.android.com") >= 0:
TypeError: 'str' does not support the buffer interface

[*] Traceback (most recent call last):
  File "artifect_find.py", line 268, in main
    parseDEX()
  File "artifect_find.py", line 157, in parseDEX
    findSuspicious(string)
  File "artifect_find.py", line 124, in findSuspicious
    if url[0].find("schemas.android.com") >= 0:
TypeError: 'str' does not support the buffer interface

[*] Traceback (most recent call last):
  File "artifect_find.py", line 267, in main
    parseDEX()
  File "artifect_find.py", line 156, in parseDEX
    findSuspicious(string)
  File "artifect_find.py", line 123, in findSuspicious
    if str((url[0]).replace("b'", '')).find("schemas.android.com") >= 0:
TypeError: 'str' does not support the buffer interface

[*] Traceback (most recent call last):
  File "artifect_find.py", line 267, in main
    parseDEX()
  File "artifect_find.py", line 156, in parseDEX
    findSuspicious(string)
  File "artifect_find.py", line 124, in findSuspicious
    if (str(url[0]).replace("b'", '')) >= 0:
TypeError: unorderable types: str() >= int()

[*] Traceback (most recent call last):
  File "artifect_find.py", line 267, in main
    parseDEX()
  File "artifect_find.py", line 156, in parseDEX
    findSuspicious(string)
  File "artifect_find.py", line 124, in findSuspicious
    if (url[0].replace("b'", '')) >= 0:
TypeError: 'str' does not support the buffer interface

[*] Traceback (most recent call last):
  File "artifect_find.py", line 267, in main
    parseDEX()
  File "artifect_find.py", line 156, in parseDEX
    findSuspicious(string)
  File "artifect_find.py", line 124, in findSuspicious
    if (str(url[0]).replace("b'", '')) >= 0:
TypeError: unorderable types: str() >= int()

[*] Traceback (most recent call last):
  File "artifect_find.py", line 267, in main
    parseDEX()
  File "artifect_find.py", line 156, in parseDEX
    findSuspicious(string)
  File "artifect_find.py", line 124, in findSuspicious
    if int(str(url[0]).replace("b'", '')) >= 0:
ValueError: invalid literal for int() with base 10: "http://165.132.221.240:83/api/android/getfile'"

[*] Traceback (most recent call last):
  File "artifect_find.py", line 266, in main
    getManifest(apkfile)
  File "artifect_find.py", line 99, in getManifest
    print (line.split('.')[-1]).replace('\'\n', '')
AttributeError: 'NoneType' object has no attribute 'replace'

[*] Traceback (most recent call last):
  File "artifect_find.py", line 266, in main
    getManifest(apkfile)
  File "artifect_find.py", line 99, in getManifest
    print (line.split('.')[-1]).replace('\'', '')
AttributeError: 'NoneType' object has no attribute 'replace'

[*] Traceback (most recent call last):
  File "artifect_find.py", line 266, in main
    getManifest(apkfile)
  File "artifect_find.py", line 99, in getManifest
    print (line.split('.')[-1]).replace("'\n", '')
AttributeError: 'NoneType' object has no attribute 'replace'

[*] Traceback (most recent call last):
  File "artifect_find.py", line 266, in main
    getManifest(apkfile)
  File "artifect_find.py", line 99, in getManifest
    print (line.split('.')[-1]).replace("\n", '')
AttributeError: 'NoneType' object has no attribute 'replace'

[*] Traceback (most recent call last):
  File "artifect_find.py", line 266, in main
    getManifest(apkfile)
  File "artifect_find.py", line 99, in getManifest
    print (str(line.split('.')[-1])).replace("\'", "")
AttributeError: 'NoneType' object has no attribute 'replace'

[*] Traceback (most recent call last):
  File "artifect_find.py", line 266, in main
    getManifest(apkfile)
  File "artifect_find.py", line 99, in getManifest
    print (line.split('.')[-1]).split('\'')[0]
AttributeError: 'NoneType' object has no attribute 'split'

[*] Traceback (most recent call last):
  File "artifect_find.py", line 266, in main
    getManifest(apkfile)
  File "artifect_find.py", line 99, in getManifest
    print (line.split('.')[-1]).split("'")[0]
AttributeError: 'NoneType' object has no attribute 'split'

[*] Traceback (most recent call last):
  File "artifect_find.py", line 266, in main
    getManifest(apkfile)
  File "artifect_find.py", line 99, in getManifest
    print (str(line.split('.')[-1])).split("'")[0]
AttributeError: 'NoneType' object has no attribute 'split'

[*] Traceback (most recent call last):
  File "artifect_find.py", line 266, in main
    getManifest(apkfile)
  File "artifect_find.py", line 99, in getManifest
    print (line.split('\'')[-2]).split('.')[-1]
AttributeError: 'NoneType' object has no attribute 'split'

[*] Traceback (most recent call last):
  File "artifect_find.py", line 266, in main
    getManifest(apkfile)
  File "artifect_find.py", line 99, in getManifest
    print (str(line.split('\'')[-2])).split('.')[-1]
AttributeError: 'NoneType' object has no attribute 'split'

[*] Traceback (most recent call last):
  File "artifect_find.py", line 268, in main
    getManifest(cur,apkfile)
  File "artifect_find.py", line 105, in getManifest
    cur.execute("INSERT INTO APK_XML(PERMISSION) VALUES(%s);" %mysql_list)
  File "/usr/local/lib/python3.4/dist-packages/pymysql/cursors.py", line 166, in execute
    result = self._query(query)
  File "/usr/local/lib/python3.4/dist-packages/pymysql/cursors.py", line 322, in _query
    conn.query(q)
  File "/usr/local/lib/python3.4/dist-packages/pymysql/connections.py", line 835, in query
    self._affected_rows = self._read_query_result(unbuffered=unbuffered)
  File "/usr/local/lib/python3.4/dist-packages/pymysql/connections.py", line 1019, in _read_query_result
    result.read()
  File "/usr/local/lib/python3.4/dist-packages/pymysql/connections.py", line 1302, in read
    first_packet = self.connection._read_packet()
  File "/usr/local/lib/python3.4/dist-packages/pymysql/connections.py", line 981, in _read_packet
    packet.check_error()
  File "/usr/local/lib/python3.4/dist-packages/pymysql/connections.py", line 393, in check_error
    err.raise_mysql_exception(self._data)
  File "/usr/local/lib/python3.4/dist-packages/pymysql/err.py", line 107, in raise_mysql_exception
    raise errorclass(errno, errval)
pymysql.err.ProgrammingError: (1064, "You have an error in your SQL syntax; check the manual that corresponds to your MySQL server version for the right syntax to use near ')' at line 1")

[*] Traceback (most recent call last):
  File "artifect_find.py", line 268, in main
    getManifest(cur,apkfile)
  File "artifect_find.py", line 105, in getManifest
    cur.execute("INSERT INTO APK_XML(PERMISSION) VALUES(mysql_list)")
  File "/usr/local/lib/python3.4/dist-packages/pymysql/cursors.py", line 166, in execute
    result = self._query(query)
  File "/usr/local/lib/python3.4/dist-packages/pymysql/cursors.py", line 322, in _query
    conn.query(q)
  File "/usr/local/lib/python3.4/dist-packages/pymysql/connections.py", line 835, in query
    self._affected_rows = self._read_query_result(unbuffered=unbuffered)
  File "/usr/local/lib/python3.4/dist-packages/pymysql/connections.py", line 1019, in _read_query_result
    result.read()
  File "/usr/local/lib/python3.4/dist-packages/pymysql/connections.py", line 1302, in read
    first_packet = self.connection._read_packet()
  File "/usr/local/lib/python3.4/dist-packages/pymysql/connections.py", line 981, in _read_packet
    packet.check_error()
  File "/usr/local/lib/python3.4/dist-packages/pymysql/connections.py", line 393, in check_error
    err.raise_mysql_exception(self._data)
  File "/usr/local/lib/python3.4/dist-packages/pymysql/err.py", line 107, in raise_mysql_exception
    raise errorclass(errno, errval)
pymysql.err.InternalError: (1054, "Unknown column 'mysql_list' in 'field list'")

[*] Traceback (most recent call last):
  File "artifect_find.py", line 270, in main
    getManifest(cur,apkfile)
  File "artifect_find.py", line 107, in getManifest
    cur.execute(cmd)
  File "/usr/local/lib/python3.4/dist-packages/pymysql/cursors.py", line 166, in execute
    result = self._query(query)
  File "/usr/local/lib/python3.4/dist-packages/pymysql/cursors.py", line 322, in _query
    conn.query(q)
  File "/usr/local/lib/python3.4/dist-packages/pymysql/connections.py", line 835, in query
    self._affected_rows = self._read_query_result(unbuffered=unbuffered)
  File "/usr/local/lib/python3.4/dist-packages/pymysql/connections.py", line 1019, in _read_query_result
    result.read()
  File "/usr/local/lib/python3.4/dist-packages/pymysql/connections.py", line 1302, in read
    first_packet = self.connection._read_packet()
  File "/usr/local/lib/python3.4/dist-packages/pymysql/connections.py", line 981, in _read_packet
    packet.check_error()
  File "/usr/local/lib/python3.4/dist-packages/pymysql/connections.py", line 393, in check_error
    err.raise_mysql_exception(self._data)
  File "/usr/local/lib/python3.4/dist-packages/pymysql/err.py", line 107, in raise_mysql_exception
    raise errorclass(errno, errval)
pymysql.err.ProgrammingError: (1064, "You have an error in your SQL syntax; check the manual that corresponds to your MySQL server version for the right syntax to use near ')' at line 1")

[*] Traceback (most recent call last):
  File "artifect_find.py", line 270, in main
    getManifest(cur,apkfile)
  File "artifect_find.py", line 107, in getManifest
    cur.execute(cmd,mysql_list)
  File "/usr/local/lib/python3.4/dist-packages/pymysql/cursors.py", line 166, in execute
    result = self._query(query)
  File "/usr/local/lib/python3.4/dist-packages/pymysql/cursors.py", line 322, in _query
    conn.query(q)
  File "/usr/local/lib/python3.4/dist-packages/pymysql/connections.py", line 835, in query
    self._affected_rows = self._read_query_result(unbuffered=unbuffered)
  File "/usr/local/lib/python3.4/dist-packages/pymysql/connections.py", line 1019, in _read_query_result
    result.read()
  File "/usr/local/lib/python3.4/dist-packages/pymysql/connections.py", line 1302, in read
    first_packet = self.connection._read_packet()
  File "/usr/local/lib/python3.4/dist-packages/pymysql/connections.py", line 981, in _read_packet
    packet.check_error()
  File "/usr/local/lib/python3.4/dist-packages/pymysql/connections.py", line 393, in check_error
    err.raise_mysql_exception(self._data)
  File "/usr/local/lib/python3.4/dist-packages/pymysql/err.py", line 107, in raise_mysql_exception
    raise errorclass(errno, errval)
pymysql.err.IntegrityError: (1452, 'Cannot add or update a child row: a foreign key constraint fails (`rezeroid`.`APK_XML`, CONSTRAINT `APK_XML_ibfk_1` FOREIGN KEY (`CASE_ID`, `M_ID`) REFERENCES `CASE_INFO` (`CASE_ID`, `M_ID`))')

[*] Traceback (most recent call last):
  File "artifect_find.py", line 271, in main
    getManifest(cur,apkfile)
  File "artifect_find.py", line 107, in getManifest
    cur.execute(cmd,mysql_list)
  File "/usr/local/lib/python3.4/dist-packages/pymysql/cursors.py", line 166, in execute
    result = self._query(query)
  File "/usr/local/lib/python3.4/dist-packages/pymysql/cursors.py", line 322, in _query
    conn.query(q)
  File "/usr/local/lib/python3.4/dist-packages/pymysql/connections.py", line 835, in query
    self._affected_rows = self._read_query_result(unbuffered=unbuffered)
  File "/usr/local/lib/python3.4/dist-packages/pymysql/connections.py", line 1019, in _read_query_result
    result.read()
  File "/usr/local/lib/python3.4/dist-packages/pymysql/connections.py", line 1302, in read
    first_packet = self.connection._read_packet()
  File "/usr/local/lib/python3.4/dist-packages/pymysql/connections.py", line 981, in _read_packet
    packet.check_error()
  File "/usr/local/lib/python3.4/dist-packages/pymysql/connections.py", line 393, in check_error
    err.raise_mysql_exception(self._data)
  File "/usr/local/lib/python3.4/dist-packages/pymysql/err.py", line 107, in raise_mysql_exception
    raise errorclass(errno, errval)
pymysql.err.IntegrityError: (1452, 'Cannot add or update a child row: a foreign key constraint fails (`rezeroid`.`APK_XML`, CONSTRAINT `APK_XML_ibfk_1` FOREIGN KEY (`CASE_ID`, `M_ID`) REFERENCES `CASE_INFO` (`CASE_ID`, `M_ID`))')

[*] Traceback (most recent call last):
  File "/usr/local/lib/python3.4/dist-packages/pymysql/connections.py", line 890, in connect
    (self.host, self.port), self.connect_timeout)
  File "/usr/lib/python3.4/socket.py", line 512, in create_connection
    raise err
  File "/usr/lib/python3.4/socket.py", line 503, in create_connection
    sock.connect(sa)
OSError: [Errno 101] Network is unreachable

During handling of the above exception, another exception occurred:

Traceback (most recent call last):
  File "artifect_find.py", line 265, in main
    con = pymysql.connect(host='165.132.221.252',user='root',passwd='keroro2424',db='rezeroid')
  File "/usr/local/lib/python3.4/dist-packages/pymysql/__init__.py", line 90, in Connect
    return Connection(*args, **kwargs)
  File "/usr/local/lib/python3.4/dist-packages/pymysql/connections.py", line 688, in __init__
    self.connect()
  File "/usr/local/lib/python3.4/dist-packages/pymysql/connections.py", line 937, in connect
    raise exc
pymysql.err.OperationalError: (2003, "Can't connect to MySQL server on '165.132.221.252' ([Errno 101] Network is unreachable)")

[*] Traceback (most recent call last):
  File "artifect_find.py", line 271, in main
    getManifest(cur,apkfile)
  File "artifect_find.py", line 107, in getManifest
    cur.execute(cmd,mysql_list)
  File "/usr/local/lib/python3.4/dist-packages/pymysql/cursors.py", line 166, in execute
    result = self._query(query)
  File "/usr/local/lib/python3.4/dist-packages/pymysql/cursors.py", line 322, in _query
    conn.query(q)
  File "/usr/local/lib/python3.4/dist-packages/pymysql/connections.py", line 835, in query
    self._affected_rows = self._read_query_result(unbuffered=unbuffered)
  File "/usr/local/lib/python3.4/dist-packages/pymysql/connections.py", line 1019, in _read_query_result
    result.read()
  File "/usr/local/lib/python3.4/dist-packages/pymysql/connections.py", line 1302, in read
    first_packet = self.connection._read_packet()
  File "/usr/local/lib/python3.4/dist-packages/pymysql/connections.py", line 981, in _read_packet
    packet.check_error()
  File "/usr/local/lib/python3.4/dist-packages/pymysql/connections.py", line 393, in check_error
    err.raise_mysql_exception(self._data)
  File "/usr/local/lib/python3.4/dist-packages/pymysql/err.py", line 107, in raise_mysql_exception
    raise errorclass(errno, errval)
pymysql.err.IntegrityError: (1452, 'Cannot add or update a child row: a foreign key constraint fails (`rezeroid`.`APK_XML`, CONSTRAINT `APK_XML_ibfk_1` FOREIGN KEY (`CASE_ID`, `M_ID`) REFERENCES `CASE_INFO` (`CASE_ID`, `M_ID`))')

[*] Traceback (most recent call last):
  File "artifect_find.py", line 271, in main
    getManifest(cur,apkfile)
  File "artifect_find.py", line 107, in getManifest
    cur.execute(cmd,mysql_list)
  File "/usr/local/lib/python3.4/dist-packages/pymysql/cursors.py", line 166, in execute
    result = self._query(query)
  File "/usr/local/lib/python3.4/dist-packages/pymysql/cursors.py", line 322, in _query
    conn.query(q)
  File "/usr/local/lib/python3.4/dist-packages/pymysql/connections.py", line 835, in query
    self._affected_rows = self._read_query_result(unbuffered=unbuffered)
  File "/usr/local/lib/python3.4/dist-packages/pymysql/connections.py", line 1019, in _read_query_result
    result.read()
  File "/usr/local/lib/python3.4/dist-packages/pymysql/connections.py", line 1302, in read
    first_packet = self.connection._read_packet()
  File "/usr/local/lib/python3.4/dist-packages/pymysql/connections.py", line 981, in _read_packet
    packet.check_error()
  File "/usr/local/lib/python3.4/dist-packages/pymysql/connections.py", line 393, in check_error
    err.raise_mysql_exception(self._data)
  File "/usr/local/lib/python3.4/dist-packages/pymysql/err.py", line 107, in raise_mysql_exception
    raise errorclass(errno, errval)
pymysql.err.IntegrityError: (1062, "Duplicate entry 'a-aa' for key 'PRIMARY'")

[*] Traceback (most recent call last):
  File "artifect_find.py", line 271, in main
    getManifest(cur,apkfile)
  File "artifect_find.py", line 107, in getManifest
    cur.execute(cmd,mysql_list)
  File "/usr/local/lib/python3.4/dist-packages/pymysql/cursors.py", line 166, in execute
    result = self._query(query)
  File "/usr/local/lib/python3.4/dist-packages/pymysql/cursors.py", line 322, in _query
    conn.query(q)
  File "/usr/local/lib/python3.4/dist-packages/pymysql/connections.py", line 835, in query
    self._affected_rows = self._read_query_result(unbuffered=unbuffered)
  File "/usr/local/lib/python3.4/dist-packages/pymysql/connections.py", line 1019, in _read_query_result
    result.read()
  File "/usr/local/lib/python3.4/dist-packages/pymysql/connections.py", line 1302, in read
    first_packet = self.connection._read_packet()
  File "/usr/local/lib/python3.4/dist-packages/pymysql/connections.py", line 981, in _read_packet
    packet.check_error()
  File "/usr/local/lib/python3.4/dist-packages/pymysql/connections.py", line 393, in check_error
    err.raise_mysql_exception(self._data)
  File "/usr/local/lib/python3.4/dist-packages/pymysql/err.py", line 107, in raise_mysql_exception
    raise errorclass(errno, errval)
pymysql.err.IntegrityError: (1062, "Duplicate entry 'a-aa' for key 'PRIMARY'")

[*] Traceback (most recent call last):
  File "artifect_find.py", line 271, in main
    getManifest(cur,apkfile)
  File "artifect_find.py", line 107, in getManifest
    cur.execute(cmd,mysql_list)
  File "/usr/local/lib/python3.4/dist-packages/pymysql/cursors.py", line 166, in execute
    result = self._query(query)
  File "/usr/local/lib/python3.4/dist-packages/pymysql/cursors.py", line 322, in _query
    conn.query(q)
  File "/usr/local/lib/python3.4/dist-packages/pymysql/connections.py", line 835, in query
    self._affected_rows = self._read_query_result(unbuffered=unbuffered)
  File "/usr/local/lib/python3.4/dist-packages/pymysql/connections.py", line 1019, in _read_query_result
    result.read()
  File "/usr/local/lib/python3.4/dist-packages/pymysql/connections.py", line 1302, in read
    first_packet = self.connection._read_packet()
  File "/usr/local/lib/python3.4/dist-packages/pymysql/connections.py", line 981, in _read_packet
    packet.check_error()
  File "/usr/local/lib/python3.4/dist-packages/pymysql/connections.py", line 393, in check_error
    err.raise_mysql_exception(self._data)
  File "/usr/local/lib/python3.4/dist-packages/pymysql/err.py", line 107, in raise_mysql_exception
    raise errorclass(errno, errval)
pymysql.err.IntegrityError: (1062, "Duplicate entry 'a-aa' for key 'PRIMARY'")

[*] Traceback (most recent call last):
  File "artifect_find.py", line 271, in main
    getManifest(cur,apkfile)
  File "artifect_find.py", line 107, in getManifest
    cur.execute(cmd,(mysql_list,"a","aa"))
  File "/usr/local/lib/python3.4/dist-packages/pymysql/cursors.py", line 166, in execute
    result = self._query(query)
  File "/usr/local/lib/python3.4/dist-packages/pymysql/cursors.py", line 322, in _query
    conn.query(q)
  File "/usr/local/lib/python3.4/dist-packages/pymysql/connections.py", line 835, in query
    self._affected_rows = self._read_query_result(unbuffered=unbuffered)
  File "/usr/local/lib/python3.4/dist-packages/pymysql/connections.py", line 1019, in _read_query_result
    result.read()
  File "/usr/local/lib/python3.4/dist-packages/pymysql/connections.py", line 1302, in read
    first_packet = self.connection._read_packet()
  File "/usr/local/lib/python3.4/dist-packages/pymysql/connections.py", line 981, in _read_packet
    packet.check_error()
  File "/usr/local/lib/python3.4/dist-packages/pymysql/connections.py", line 393, in check_error
    err.raise_mysql_exception(self._data)
  File "/usr/local/lib/python3.4/dist-packages/pymysql/err.py", line 107, in raise_mysql_exception
    raise errorclass(errno, errval)
pymysql.err.IntegrityError: (1062, "Duplicate entry 'a-aa' for key 'PRIMARY'")

[*] Traceback (most recent call last):
  File "artifect_find.py", line 271, in main
    getManifest(cur,apkfile)
  File "artifect_find.py", line 107, in getManifest
    cur.execute(cmd,mysql_list)
  File "/usr/local/lib/python3.4/dist-packages/pymysql/cursors.py", line 166, in execute
    result = self._query(query)
  File "/usr/local/lib/python3.4/dist-packages/pymysql/cursors.py", line 322, in _query
    conn.query(q)
  File "/usr/local/lib/python3.4/dist-packages/pymysql/connections.py", line 835, in query
    self._affected_rows = self._read_query_result(unbuffered=unbuffered)
  File "/usr/local/lib/python3.4/dist-packages/pymysql/connections.py", line 1019, in _read_query_result
    result.read()
  File "/usr/local/lib/python3.4/dist-packages/pymysql/connections.py", line 1302, in read
    first_packet = self.connection._read_packet()
  File "/usr/local/lib/python3.4/dist-packages/pymysql/connections.py", line 981, in _read_packet
    packet.check_error()
  File "/usr/local/lib/python3.4/dist-packages/pymysql/connections.py", line 393, in check_error
    err.raise_mysql_exception(self._data)
  File "/usr/local/lib/python3.4/dist-packages/pymysql/err.py", line 107, in raise_mysql_exception
    raise errorclass(errno, errval)
pymysql.err.IntegrityError: (1048, "Column 'CASE_ID' cannot be null")

[*] Traceback (most recent call last):
  File "artifect_find.py", line 271, in main
    getManifest(cur,apkfile)
  File "artifect_find.py", line 107, in getManifest
    cur.execute(cmd,mysql_list)
  File "/usr/local/lib/python3.4/dist-packages/pymysql/cursors.py", line 166, in execute
    result = self._query(query)
  File "/usr/local/lib/python3.4/dist-packages/pymysql/cursors.py", line 322, in _query
    conn.query(q)
  File "/usr/local/lib/python3.4/dist-packages/pymysql/connections.py", line 835, in query
    self._affected_rows = self._read_query_result(unbuffered=unbuffered)
  File "/usr/local/lib/python3.4/dist-packages/pymysql/connections.py", line 1019, in _read_query_result
    result.read()
  File "/usr/local/lib/python3.4/dist-packages/pymysql/connections.py", line 1302, in read
    first_packet = self.connection._read_packet()
  File "/usr/local/lib/python3.4/dist-packages/pymysql/connections.py", line 981, in _read_packet
    packet.check_error()
  File "/usr/local/lib/python3.4/dist-packages/pymysql/connections.py", line 393, in check_error
    err.raise_mysql_exception(self._data)
  File "/usr/local/lib/python3.4/dist-packages/pymysql/err.py", line 107, in raise_mysql_exception
    raise errorclass(errno, errval)
pymysql.err.IntegrityError: (1062, "Duplicate entry 'a-aa' for key 'PRIMARY'")

[*] Traceback (most recent call last):
  File "artifect_find.py", line 271, in main
    getManifest(cur,apkfile)
  File "artifect_find.py", line 107, in getManifest
    cur.execute(cmd,mysql_list)
  File "/usr/local/lib/python3.4/dist-packages/pymysql/cursors.py", line 166, in execute
    result = self._query(query)
  File "/usr/local/lib/python3.4/dist-packages/pymysql/cursors.py", line 322, in _query
    conn.query(q)
  File "/usr/local/lib/python3.4/dist-packages/pymysql/connections.py", line 835, in query
    self._affected_rows = self._read_query_result(unbuffered=unbuffered)
  File "/usr/local/lib/python3.4/dist-packages/pymysql/connections.py", line 1019, in _read_query_result
    result.read()
  File "/usr/local/lib/python3.4/dist-packages/pymysql/connections.py", line 1302, in read
    first_packet = self.connection._read_packet()
  File "/usr/local/lib/python3.4/dist-packages/pymysql/connections.py", line 981, in _read_packet
    packet.check_error()
  File "/usr/local/lib/python3.4/dist-packages/pymysql/connections.py", line 393, in check_error
    err.raise_mysql_exception(self._data)
  File "/usr/local/lib/python3.4/dist-packages/pymysql/err.py", line 107, in raise_mysql_exception
    raise errorclass(errno, errval)
pymysql.err.IntegrityError: (1452, 'Cannot add or update a child row: a foreign key constraint fails (`rezeroid`.`APK_XML`, CONSTRAINT `APK_XML_ibfk_1` FOREIGN KEY (`CASE_ID`, `M_ID`) REFERENCES `CASE_INFO` (`CASE_ID`, `M_ID`))')

[*] Traceback (most recent call last):
  File "artifect_find.py", line 271, in main
    getManifest(cur,apkfile)
  File "artifect_find.py", line 107, in getManifest
    cur.execute(cmd,mysql_list)
  File "/usr/local/lib/python3.4/dist-packages/pymysql/cursors.py", line 166, in execute
    result = self._query(query)
  File "/usr/local/lib/python3.4/dist-packages/pymysql/cursors.py", line 322, in _query
    conn.query(q)
  File "/usr/local/lib/python3.4/dist-packages/pymysql/connections.py", line 835, in query
    self._affected_rows = self._read_query_result(unbuffered=unbuffered)
  File "/usr/local/lib/python3.4/dist-packages/pymysql/connections.py", line 1019, in _read_query_result
    result.read()
  File "/usr/local/lib/python3.4/dist-packages/pymysql/connections.py", line 1302, in read
    first_packet = self.connection._read_packet()
  File "/usr/local/lib/python3.4/dist-packages/pymysql/connections.py", line 981, in _read_packet
    packet.check_error()
  File "/usr/local/lib/python3.4/dist-packages/pymysql/connections.py", line 393, in check_error
    err.raise_mysql_exception(self._data)
  File "/usr/local/lib/python3.4/dist-packages/pymysql/err.py", line 107, in raise_mysql_exception
    raise errorclass(errno, errval)
pymysql.err.IntegrityError: (1452, 'Cannot add or update a child row: a foreign key constraint fails (`rezeroid`.`APK_XML`, CONSTRAINT `APK_XML_ibfk_1` FOREIGN KEY (`CASE_ID`, `M_ID`) REFERENCES `CASE_INFO` (`CASE_ID`, `M_ID`))')

[*] Traceback (most recent call last):
  File "artifect_find.py", line 271, in main
    getManifest(cur,apkfile)
  File "artifect_find.py", line 107, in getManifest
    cur.execute(cmd,mysql_list)
  File "/usr/local/lib/python3.4/dist-packages/pymysql/cursors.py", line 166, in execute
    result = self._query(query)
  File "/usr/local/lib/python3.4/dist-packages/pymysql/cursors.py", line 322, in _query
    conn.query(q)
  File "/usr/local/lib/python3.4/dist-packages/pymysql/connections.py", line 835, in query
    self._affected_rows = self._read_query_result(unbuffered=unbuffered)
  File "/usr/local/lib/python3.4/dist-packages/pymysql/connections.py", line 1019, in _read_query_result
    result.read()
  File "/usr/local/lib/python3.4/dist-packages/pymysql/connections.py", line 1302, in read
    first_packet = self.connection._read_packet()
  File "/usr/local/lib/python3.4/dist-packages/pymysql/connections.py", line 981, in _read_packet
    packet.check_error()
  File "/usr/local/lib/python3.4/dist-packages/pymysql/connections.py", line 393, in check_error
    err.raise_mysql_exception(self._data)
  File "/usr/local/lib/python3.4/dist-packages/pymysql/err.py", line 107, in raise_mysql_exception
    raise errorclass(errno, errval)
pymysql.err.IntegrityError: (1062, "Duplicate entry 'a-aa' for key 'PRIMARY'")

[*] Traceback (most recent call last):
  File "artifect_find.py", line 274, in main
    parseDEX(cur)
  File "artifect_find.py", line 163, in parseDEX
    findSuspicious(cur,string)
  File "artifect_find.py", line 149, in findSuspicious
    cur.execute(cmd,(urllist,emaillist,iplist,phonelist))
  File "/usr/local/lib/python3.4/dist-packages/pymysql/cursors.py", line 166, in execute
    result = self._query(query)
  File "/usr/local/lib/python3.4/dist-packages/pymysql/cursors.py", line 322, in _query
    conn.query(q)
  File "/usr/local/lib/python3.4/dist-packages/pymysql/connections.py", line 835, in query
    self._affected_rows = self._read_query_result(unbuffered=unbuffered)
  File "/usr/local/lib/python3.4/dist-packages/pymysql/connections.py", line 1019, in _read_query_result
    result.read()
  File "/usr/local/lib/python3.4/dist-packages/pymysql/connections.py", line 1302, in read
    first_packet = self.connection._read_packet()
  File "/usr/local/lib/python3.4/dist-packages/pymysql/connections.py", line 981, in _read_packet
    packet.check_error()
  File "/usr/local/lib/python3.4/dist-packages/pymysql/connections.py", line 393, in check_error
    err.raise_mysql_exception(self._data)
  File "/usr/local/lib/python3.4/dist-packages/pymysql/err.py", line 107, in raise_mysql_exception
    raise errorclass(errno, errval)
pymysql.err.IntegrityError: (1452, 'Cannot add or update a child row: a foreign key constraint fails (`rezeroid`.`ARTIFACT_INFO`, CONSTRAINT `ARTIFACT_INFO_ibfk_1` FOREIGN KEY (`CASE_ID`, `M_ID`) REFERENCES `CASE_INFO` (`CASE_ID`, `M_ID`))')

[*] Traceback (most recent call last):
  File "artifect_find.py", line 271, in main
    getManifest(cur,apkfile)
  File "artifect_find.py", line 107, in getManifest
    cur.execute(cmd,mysql_list)
  File "/usr/local/lib/python3.4/dist-packages/pymysql/cursors.py", line 166, in execute
    result = self._query(query)
  File "/usr/local/lib/python3.4/dist-packages/pymysql/cursors.py", line 322, in _query
    conn.query(q)
  File "/usr/local/lib/python3.4/dist-packages/pymysql/connections.py", line 835, in query
    self._affected_rows = self._read_query_result(unbuffered=unbuffered)
  File "/usr/local/lib/python3.4/dist-packages/pymysql/connections.py", line 1019, in _read_query_result
    result.read()
  File "/usr/local/lib/python3.4/dist-packages/pymysql/connections.py", line 1302, in read
    first_packet = self.connection._read_packet()
  File "/usr/local/lib/python3.4/dist-packages/pymysql/connections.py", line 981, in _read_packet
    packet.check_error()
  File "/usr/local/lib/python3.4/dist-packages/pymysql/connections.py", line 393, in check_error
    err.raise_mysql_exception(self._data)
  File "/usr/local/lib/python3.4/dist-packages/pymysql/err.py", line 107, in raise_mysql_exception
    raise errorclass(errno, errval)
pymysql.err.InternalError: (1054, "Unknown column 'qqqq' in 'field list'")

[*] Traceback (most recent call last):
  File "artifect_find.py", line 274, in main
    parseDEX(cur)
  File "artifect_find.py", line 163, in parseDEX
    findSuspicious(cur,string)
  File "artifect_find.py", line 149, in findSuspicious
    cur.execute(cmd,(urllist,emaillist,iplist,phonelist))
  File "/usr/local/lib/python3.4/dist-packages/pymysql/cursors.py", line 166, in execute
    result = self._query(query)
  File "/usr/local/lib/python3.4/dist-packages/pymysql/cursors.py", line 322, in _query
    conn.query(q)
  File "/usr/local/lib/python3.4/dist-packages/pymysql/connections.py", line 835, in query
    self._affected_rows = self._read_query_result(unbuffered=unbuffered)
  File "/usr/local/lib/python3.4/dist-packages/pymysql/connections.py", line 1019, in _read_query_result
    result.read()
  File "/usr/local/lib/python3.4/dist-packages/pymysql/connections.py", line 1302, in read
    first_packet = self.connection._read_packet()
  File "/usr/local/lib/python3.4/dist-packages/pymysql/connections.py", line 981, in _read_packet
    packet.check_error()
  File "/usr/local/lib/python3.4/dist-packages/pymysql/connections.py", line 393, in check_error
    err.raise_mysql_exception(self._data)
  File "/usr/local/lib/python3.4/dist-packages/pymysql/err.py", line 107, in raise_mysql_exception
    raise errorclass(errno, errval)
pymysql.err.IntegrityError: (1452, 'Cannot add or update a child row: a foreign key constraint fails (`rezeroid`.`ARTIFACT_INFO`, CONSTRAINT `ARTIFACT_INFO_ibfk_1` FOREIGN KEY (`CASE_ID`, `M_ID`) REFERENCES `CASE_INFO` (`CASE_ID`, `M_ID`))')

[*] Traceback (most recent call last):
  File "artifect_find.py", line 274, in main
    parseDEX(cur)
  File "artifect_find.py", line 163, in parseDEX
    findSuspicious(cur,string)
  File "artifect_find.py", line 149, in findSuspicious
    cur.execute(cmd,(urllist,emaillist,iplist,phonelist))
  File "/usr/local/lib/python3.4/dist-packages/pymysql/cursors.py", line 166, in execute
    result = self._query(query)
  File "/usr/local/lib/python3.4/dist-packages/pymysql/cursors.py", line 322, in _query
    conn.query(q)
  File "/usr/local/lib/python3.4/dist-packages/pymysql/connections.py", line 835, in query
    self._affected_rows = self._read_query_result(unbuffered=unbuffered)
  File "/usr/local/lib/python3.4/dist-packages/pymysql/connections.py", line 1019, in _read_query_result
    result.read()
  File "/usr/local/lib/python3.4/dist-packages/pymysql/connections.py", line 1302, in read
    first_packet = self.connection._read_packet()
  File "/usr/local/lib/python3.4/dist-packages/pymysql/connections.py", line 981, in _read_packet
    packet.check_error()
  File "/usr/local/lib/python3.4/dist-packages/pymysql/connections.py", line 393, in check_error
    err.raise_mysql_exception(self._data)
  File "/usr/local/lib/python3.4/dist-packages/pymysql/err.py", line 107, in raise_mysql_exception
    raise errorclass(errno, errval)
pymysql.err.IntegrityError: (1452, 'Cannot add or update a child row: a foreign key constraint fails (`rezeroid`.`ARTIFACT_INFO`, CONSTRAINT `ARTIFACT_INFO_ibfk_1` FOREIGN KEY (`CASE_ID`, `M_ID`) REFERENCES `CASE_INFO` (`CASE_ID`, `M_ID`))')

[*] Traceback (most recent call last):
  File "artifect_find.py", line 274, in main
    parseDEX(cur)
  File "artifect_find.py", line 163, in parseDEX
    findSuspicious(cur,string)
  File "artifect_find.py", line 149, in findSuspicious
    cur.execute(cmd,(urllist,emaillist,iplist,phonelist))
  File "/usr/local/lib/python3.4/dist-packages/pymysql/cursors.py", line 166, in execute
    result = self._query(query)
  File "/usr/local/lib/python3.4/dist-packages/pymysql/cursors.py", line 322, in _query
    conn.query(q)
  File "/usr/local/lib/python3.4/dist-packages/pymysql/connections.py", line 835, in query
    self._affected_rows = self._read_query_result(unbuffered=unbuffered)
  File "/usr/local/lib/python3.4/dist-packages/pymysql/connections.py", line 1019, in _read_query_result
    result.read()
  File "/usr/local/lib/python3.4/dist-packages/pymysql/connections.py", line 1302, in read
    first_packet = self.connection._read_packet()
  File "/usr/local/lib/python3.4/dist-packages/pymysql/connections.py", line 981, in _read_packet
    packet.check_error()
  File "/usr/local/lib/python3.4/dist-packages/pymysql/connections.py", line 393, in check_error
    err.raise_mysql_exception(self._data)
  File "/usr/local/lib/python3.4/dist-packages/pymysql/err.py", line 107, in raise_mysql_exception
    raise errorclass(errno, errval)
pymysql.err.IntegrityError: (1452, 'Cannot add or update a child row: a foreign key constraint fails (`rezeroid`.`ARTIFACT_INFO`, CONSTRAINT `ARTIFACT_INFO_ibfk_1` FOREIGN KEY (`CASE_ID`, `M_ID`) REFERENCES `CASE_INFO` (`CASE_ID`, `M_ID`))')

[*] Traceback (most recent call last):
  File "/usr/local/lib/python3.4/dist-packages/pymysql/connections.py", line 988, in _read_bytes
    data = self._rfile.read(num_bytes)
  File "/usr/lib/python3.4/socket.py", line 374, in readinto
    return self._sock.recv_into(b)
ConnectionResetError: [Errno 104] Connection reset by peer

During handling of the above exception, another exception occurred:

Traceback (most recent call last):
  File "artifect_find.py", line 265, in main
    con = pymysql.connect(host='165.132.221.252',user='root',passwd='keroro2424',db='rezeroid')
  File "/usr/local/lib/python3.4/dist-packages/pymysql/__init__.py", line 90, in Connect
    return Connection(*args, **kwargs)
  File "/usr/local/lib/python3.4/dist-packages/pymysql/connections.py", line 688, in __init__
    self.connect()
  File "/usr/local/lib/python3.4/dist-packages/pymysql/connections.py", line 905, in connect
    self._get_server_information()
  File "/usr/local/lib/python3.4/dist-packages/pymysql/connections.py", line 1207, in _get_server_information
    packet = self._read_packet()
  File "/usr/local/lib/python3.4/dist-packages/pymysql/connections.py", line 961, in _read_packet
    packet_header = self._read_bytes(4)
  File "/usr/local/lib/python3.4/dist-packages/pymysql/connections.py", line 995, in _read_bytes
    "Lost connection to MySQL server during query (%s)" % (e,))
pymysql.err.OperationalError: (2013, 'Lost connection to MySQL server during query ([Errno 104] Connection reset by peer)')

[*] Traceback (most recent call last):
  File "/usr/local/lib/python3.4/dist-packages/pymysql/connections.py", line 988, in _read_bytes
    data = self._rfile.read(num_bytes)
  File "/usr/lib/python3.4/socket.py", line 374, in readinto
    return self._sock.recv_into(b)
ConnectionResetError: [Errno 104] Connection reset by peer

During handling of the above exception, another exception occurred:

Traceback (most recent call last):
  File "artifect_find.py", line 266, in main
    con = pymysql.connect(host='165.132.221.252',user='root',passwd='keroro2424',db='rezeroid')
  File "/usr/local/lib/python3.4/dist-packages/pymysql/__init__.py", line 90, in Connect
    return Connection(*args, **kwargs)
  File "/usr/local/lib/python3.4/dist-packages/pymysql/connections.py", line 688, in __init__
    self.connect()
  File "/usr/local/lib/python3.4/dist-packages/pymysql/connections.py", line 905, in connect
    self._get_server_information()
  File "/usr/local/lib/python3.4/dist-packages/pymysql/connections.py", line 1207, in _get_server_information
    packet = self._read_packet()
  File "/usr/local/lib/python3.4/dist-packages/pymysql/connections.py", line 961, in _read_packet
    packet_header = self._read_bytes(4)
  File "/usr/local/lib/python3.4/dist-packages/pymysql/connections.py", line 995, in _read_bytes
    "Lost connection to MySQL server during query (%s)" % (e,))
pymysql.err.OperationalError: (2013, 'Lost connection to MySQL server during query ([Errno 104] Connection reset by peer)')

[*] Traceback (most recent call last):
  File "artifect_find.py", line 272, in main
    getManifest(cur,apkfile)
  File "artifect_find.py", line 108, in getManifest
    cur.execute(cmd)
  File "/usr/local/lib/python3.4/dist-packages/pymysql/cursors.py", line 166, in execute
    result = self._query(query)
  File "/usr/local/lib/python3.4/dist-packages/pymysql/cursors.py", line 322, in _query
    conn.query(q)
  File "/usr/local/lib/python3.4/dist-packages/pymysql/connections.py", line 835, in query
    self._affected_rows = self._read_query_result(unbuffered=unbuffered)
  File "/usr/local/lib/python3.4/dist-packages/pymysql/connections.py", line 1019, in _read_query_result
    result.read()
  File "/usr/local/lib/python3.4/dist-packages/pymysql/connections.py", line 1302, in read
    first_packet = self.connection._read_packet()
  File "/usr/local/lib/python3.4/dist-packages/pymysql/connections.py", line 981, in _read_packet
    packet.check_error()
  File "/usr/local/lib/python3.4/dist-packages/pymysql/connections.py", line 393, in check_error
    err.raise_mysql_exception(self._data)
  File "/usr/local/lib/python3.4/dist-packages/pymysql/err.py", line 107, in raise_mysql_exception
    raise errorclass(errno, errval)
pymysql.err.ProgrammingError: (1064, "You have an error in your SQL syntax; check the manual that corresponds to your MySQL server version for the right syntax to use near ' 'qqqq', 'qqq')' at line 1")

[*] Traceback (most recent call last):
  File "artifect_find.py", line 272, in main
    getManifest(cur,apkfile)
  File "artifect_find.py", line 106, in getManifest
    cmd = "INSERT INTO APK_XML VALUES (null, %s, $s, $s)" % (mysql_list,'qqqq','qqq')
TypeError: not all arguments converted during string formatting

[*] Traceback (most recent call last):
  File "artifect_find.py", line 272, in main
    getManifest(cur,apkfile)
  File "artifect_find.py", line 107, in getManifest
    cur.execute(cmd, (mysql_list, 'qqqq', 'qqq'))
  File "/usr/local/lib/python3.4/dist-packages/pymysql/cursors.py", line 164, in execute
    query = self.mogrify(query, args)
  File "/usr/local/lib/python3.4/dist-packages/pymysql/cursors.py", line 143, in mogrify
    query = query % self._escape_args(args, conn)
TypeError: not all arguments converted during string formatting

[*] Traceback (most recent call last):
  File "artifect_find.py", line 275, in main
    parseDEX(cur)
  File "artifect_find.py", line 164, in parseDEX
    findSuspicious(cur,string)
  File "artifect_find.py", line 150, in findSuspicious
    cur.execute(cmd,(urllist,emaillist,iplist,phonelist))
  File "/usr/local/lib/python3.4/dist-packages/pymysql/cursors.py", line 166, in execute
    result = self._query(query)
  File "/usr/local/lib/python3.4/dist-packages/pymysql/cursors.py", line 322, in _query
    conn.query(q)
  File "/usr/local/lib/python3.4/dist-packages/pymysql/connections.py", line 835, in query
    self._affected_rows = self._read_query_result(unbuffered=unbuffered)
  File "/usr/local/lib/python3.4/dist-packages/pymysql/connections.py", line 1019, in _read_query_result
    result.read()
  File "/usr/local/lib/python3.4/dist-packages/pymysql/connections.py", line 1302, in read
    first_packet = self.connection._read_packet()
  File "/usr/local/lib/python3.4/dist-packages/pymysql/connections.py", line 981, in _read_packet
    packet.check_error()
  File "/usr/local/lib/python3.4/dist-packages/pymysql/connections.py", line 393, in check_error
    err.raise_mysql_exception(self._data)
  File "/usr/local/lib/python3.4/dist-packages/pymysql/err.py", line 107, in raise_mysql_exception
    raise errorclass(errno, errval)
pymysql.err.IntegrityError: (1452, 'Cannot add or update a child row: a foreign key constraint fails (`rezeroid`.`ARTIFACT_INFO`, CONSTRAINT `ARTIFACT_INFO_ibfk_1` FOREIGN KEY (`CASE_ID`, `M_ID`) REFERENCES `CASE_INFO` (`CASE_ID`, `M_ID`))')

[*] Traceback (most recent call last):
  File "artifect_find.py", line 277, in main
    parseDEX(cur)
  File "artifect_find.py", line 166, in parseDEX
    findSuspicious(cur,string)
  File "artifect_find.py", line 152, in findSuspicious
    cur.execute(cmd,(urllist,emaillist,iplist,phonelist))
  File "/usr/local/lib/python3.4/dist-packages/pymysql/cursors.py", line 166, in execute
    result = self._query(query)
  File "/usr/local/lib/python3.4/dist-packages/pymysql/cursors.py", line 322, in _query
    conn.query(q)
  File "/usr/local/lib/python3.4/dist-packages/pymysql/connections.py", line 835, in query
    self._affected_rows = self._read_query_result(unbuffered=unbuffered)
  File "/usr/local/lib/python3.4/dist-packages/pymysql/connections.py", line 1019, in _read_query_result
    result.read()
  File "/usr/local/lib/python3.4/dist-packages/pymysql/connections.py", line 1302, in read
    first_packet = self.connection._read_packet()
  File "/usr/local/lib/python3.4/dist-packages/pymysql/connections.py", line 981, in _read_packet
    packet.check_error()
  File "/usr/local/lib/python3.4/dist-packages/pymysql/connections.py", line 393, in check_error
    err.raise_mysql_exception(self._data)
  File "/usr/local/lib/python3.4/dist-packages/pymysql/err.py", line 107, in raise_mysql_exception
    raise errorclass(errno, errval)
pymysql.err.IntegrityError: (1452, 'Cannot add or update a child row: a foreign key constraint fails (`rezeroid`.`ARTIFACT_INFO`, CONSTRAINT `ARTIFACT_INFO_ibfk_1` FOREIGN KEY (`CASE_ID`, `M_ID`) REFERENCES `CASE_INFO` (`CASE_ID`, `M_ID`))')

[*] Traceback (most recent call last):
  File "artifect_find.py", line 277, in main
    parseDEX(cur)
  File "artifect_find.py", line 166, in parseDEX
    findSuspicious(cur,string)
  File "artifect_find.py", line 152, in findSuspicious
    cur.execute(cmd,(urllist,emaillist,iplist,phonelist))
  File "/usr/local/lib/python3.4/dist-packages/pymysql/cursors.py", line 166, in execute
    result = self._query(query)
  File "/usr/local/lib/python3.4/dist-packages/pymysql/cursors.py", line 322, in _query
    conn.query(q)
  File "/usr/local/lib/python3.4/dist-packages/pymysql/connections.py", line 835, in query
    self._affected_rows = self._read_query_result(unbuffered=unbuffered)
  File "/usr/local/lib/python3.4/dist-packages/pymysql/connections.py", line 1019, in _read_query_result
    result.read()
  File "/usr/local/lib/python3.4/dist-packages/pymysql/connections.py", line 1302, in read
    first_packet = self.connection._read_packet()
  File "/usr/local/lib/python3.4/dist-packages/pymysql/connections.py", line 981, in _read_packet
    packet.check_error()
  File "/usr/local/lib/python3.4/dist-packages/pymysql/connections.py", line 393, in check_error
    err.raise_mysql_exception(self._data)
  File "/usr/local/lib/python3.4/dist-packages/pymysql/err.py", line 107, in raise_mysql_exception
    raise errorclass(errno, errval)
pymysql.err.IntegrityError: (1452, 'Cannot add or update a child row: a foreign key constraint fails (`rezeroid`.`ARTIFACT_INFO`, CONSTRAINT `ARTIFACT_INFO_ibfk_1` FOREIGN KEY (`CASE_ID`, `M_ID`) REFERENCES `CASE_INFO` (`CASE_ID`, `M_ID`))')

[*] Traceback (most recent call last):
  File "artifect_find.py", line 277, in main
    parseDEX(cur)
  File "artifect_find.py", line 166, in parseDEX
    findSuspicious(cur,string)
  File "artifect_find.py", line 152, in findSuspicious
    cur.execute(cmd,(urllist,emaillist,iplist,phonelist))
  File "/usr/local/lib/python3.4/dist-packages/pymysql/cursors.py", line 166, in execute
    result = self._query(query)
  File "/usr/local/lib/python3.4/dist-packages/pymysql/cursors.py", line 322, in _query
    conn.query(q)
  File "/usr/local/lib/python3.4/dist-packages/pymysql/connections.py", line 835, in query
    self._affected_rows = self._read_query_result(unbuffered=unbuffered)
  File "/usr/local/lib/python3.4/dist-packages/pymysql/connections.py", line 1019, in _read_query_result
    result.read()
  File "/usr/local/lib/python3.4/dist-packages/pymysql/connections.py", line 1302, in read
    first_packet = self.connection._read_packet()
  File "/usr/local/lib/python3.4/dist-packages/pymysql/connections.py", line 981, in _read_packet
    packet.check_error()
  File "/usr/local/lib/python3.4/dist-packages/pymysql/connections.py", line 393, in check_error
    err.raise_mysql_exception(self._data)
  File "/usr/local/lib/python3.4/dist-packages/pymysql/err.py", line 107, in raise_mysql_exception
    raise errorclass(errno, errval)
pymysql.err.IntegrityError: (1452, 'Cannot add or update a child row: a foreign key constraint fails (`rezeroid`.`ARTIFACT_INFO`, CONSTRAINT `ARTIFACT_INFO_ibfk_1` FOREIGN KEY (`CASE_ID`, `M_ID`) REFERENCES `CASE_INFO` (`CASE_ID`, `M_ID`))')

[*] Traceback (most recent call last):
  File "artifect_find.py", line 277, in main
    parseDEX(cur)
  File "artifect_find.py", line 166, in parseDEX
    findSuspicious(cur,string)
  File "artifect_find.py", line 152, in findSuspicious
    cur.execute(cmd,(urllist,emaillist,iplist,phonelist))
  File "/usr/local/lib/python3.4/dist-packages/pymysql/cursors.py", line 166, in execute
    result = self._query(query)
  File "/usr/local/lib/python3.4/dist-packages/pymysql/cursors.py", line 322, in _query
    conn.query(q)
  File "/usr/local/lib/python3.4/dist-packages/pymysql/connections.py", line 835, in query
    self._affected_rows = self._read_query_result(unbuffered=unbuffered)
  File "/usr/local/lib/python3.4/dist-packages/pymysql/connections.py", line 1019, in _read_query_result
    result.read()
  File "/usr/local/lib/python3.4/dist-packages/pymysql/connections.py", line 1302, in read
    first_packet = self.connection._read_packet()
  File "/usr/local/lib/python3.4/dist-packages/pymysql/connections.py", line 981, in _read_packet
    packet.check_error()
  File "/usr/local/lib/python3.4/dist-packages/pymysql/connections.py", line 393, in check_error
    err.raise_mysql_exception(self._data)
  File "/usr/local/lib/python3.4/dist-packages/pymysql/err.py", line 107, in raise_mysql_exception
    raise errorclass(errno, errval)
pymysql.err.IntegrityError: (1452, 'Cannot add or update a child row: a foreign key constraint fails (`rezeroid`.`ARTIFACT_INFO`, CONSTRAINT `ARTIFACT_INFO_ibfk_1` FOREIGN KEY (`CASE_ID`, `M_ID`) REFERENCES `CASE_INFO` (`CASE_ID`, `M_ID`))')

[*] Traceback (most recent call last):
  File "/usr/local/lib/python3.4/dist-packages/pymysql/connections.py", line 988, in _read_bytes
    data = self._rfile.read(num_bytes)
  File "/usr/lib/python3.4/socket.py", line 374, in readinto
    return self._sock.recv_into(b)
ConnectionResetError: [Errno 104] Connection reset by peer

During handling of the above exception, another exception occurred:

Traceback (most recent call last):
  File "artifect_find.py", line 268, in main
    con = pymysql.connect(host='165.132.221.252',user='root',passwd='keroro2424',db='rezeroid')
  File "/usr/local/lib/python3.4/dist-packages/pymysql/__init__.py", line 90, in Connect
    return Connection(*args, **kwargs)
  File "/usr/local/lib/python3.4/dist-packages/pymysql/connections.py", line 688, in __init__
    self.connect()
  File "/usr/local/lib/python3.4/dist-packages/pymysql/connections.py", line 905, in connect
    self._get_server_information()
  File "/usr/local/lib/python3.4/dist-packages/pymysql/connections.py", line 1207, in _get_server_information
    packet = self._read_packet()
  File "/usr/local/lib/python3.4/dist-packages/pymysql/connections.py", line 961, in _read_packet
    packet_header = self._read_bytes(4)
  File "/usr/local/lib/python3.4/dist-packages/pymysql/connections.py", line 995, in _read_bytes
    "Lost connection to MySQL server during query (%s)" % (e,))
pymysql.err.OperationalError: (2013, 'Lost connection to MySQL server during query ([Errno 104] Connection reset by peer)')

[*] Traceback (most recent call last):
  File "artifect_find.py", line 277, in main
    parseDEX(cur)
  File "artifect_find.py", line 166, in parseDEX
    findSuspicious(cur,string)
  File "artifect_find.py", line 152, in findSuspicious
    cur.execute(cmd,(urllist,emaillist,iplist,phonelist,'qqqq','qqq'))
  File "/usr/local/lib/python3.4/dist-packages/pymysql/cursors.py", line 164, in execute
    query = self.mogrify(query, args)
  File "/usr/local/lib/python3.4/dist-packages/pymysql/cursors.py", line 143, in mogrify
    query = query % self._escape_args(args, conn)
TypeError: not all arguments converted during string formatting

[*] Traceback (most recent call last):
  File "artifect_find.py", line 277, in main
    parseDEX(cur)
  File "artifect_find.py", line 166, in parseDEX
    findSuspicious(cur,string)
  File "artifect_find.py", line 152, in findSuspicious
    cur.execute(cmd,(str(urllist),str(emaillist),str(iplist),str(phonelist),'qqqq','qqq'))
  File "/usr/local/lib/python3.4/dist-packages/pymysql/cursors.py", line 164, in execute
    query = self.mogrify(query, args)
  File "/usr/local/lib/python3.4/dist-packages/pymysql/cursors.py", line 143, in mogrify
    query = query % self._escape_args(args, conn)
TypeError: not all arguments converted during string formatting

